DEBUG:fuse.log-mixin:-> getattr /hi (None,)
DEBUG:fuse.log-mixin:<- getattr '[Errno 2] No such file or directory'
DEBUG:fuse:FUSE operation getattr raised a <class 'fuse.FuseOSError'>, returning errno 2.
Traceback (most recent call last):
  File "/home/etinaude/Documents/git/340/A2/fuse.py", line 731, in _wrapper
    return func(*args, **kwargs) or 0
  File "/home/etinaude/Documents/git/340/A2/fuse.py", line 771, in getattr
    return self.fgetattr(path, buf, None)
  File "/home/etinaude/Documents/git/340/A2/fuse.py", line 1024, in fgetattr
    attrs = self.operations('getattr', self._decode_optional_path(path), fh)
  File "/home/etinaude/Documents/git/340/A2/fuse.py", line 1240, in __call__
    ret = getattr(self, op)(path, *args)
  File "a2fuse2.py", line 118, in getattr
    return self.second.getattr(path)
  File "a2fuse2.py", line 35, in getattr
    raise FuseOSError(ENOENT)
fuse.FuseOSError: [Errno 2] No such file or directory
DEBUG:fuse.log-mixin:-> create /hi (33204,)
~~~~~~~~~~~~~~~~~~~~~~~~~~~~~~~~~~~~~~~~~~~~~~~~~~~~~ /hi
{'/': {'st_mode': 16877, 'st_ctime': 1602032035.7819042, 'st_mtime': 1602032035.7819042, 'st_atime': 1602032035.7819042, 'st_nlink': 2}, '/hi': {'st_mode': 33204, 'st_nlink': 1, 'st_size': 0, 'st_ctime': 1602032047.4193053, 'st_mtime': 1602032047.4193058, 'st_atime': 1602032047.419306}} ~~~~~~~~~~~~~~~~~~~~~~~~~~~~~~~~~~~~~~~~~~~~~~~~~~~~~
DEBUG:fuse.log-mixin:<- create 1
DEBUG:fuse.log-mixin:-> getattr /hi (1,)
DEBUG:fuse.log-mixin:<- getattr {'st_mode': 33204, 'st_nlink': 1, 'st_size': 0, 'st_ctime': 1602032047.4193053, 'st_mtime': 1602032047.4193058, 'st_atime': 1602032047.419306}
DEBUG:fuse.log-mixin:-> flush /hi (1,)
DEBUG:fuse.log-mixin:<- flush 0
DEBUG:fuse.log-mixin:-> getattr / (None,)
DEBUG:fuse.log-mixin:<- getattr {'st_atime': 1601978543.744611, 'st_ctime': 1601978543.7086115, 'st_gid': 1000, 'st_mode': 16893, 'st_mtime': 1601978543.7086115, 'st_nlink': 2, 'st_size': 4096, 'st_uid': 1000}
DEBUG:fuse.log-mixin:-> opendir / ()
DEBUG:fuse.log-mixin:<- opendir 0
DEBUG:fuse.log-mixin:-> readdir / (0,)
DEBUG:fuse.log-mixin:<- readdir <generator object Fuse2.readdir at 0x7f46719b0510>
DEBUG:fuse.log-mixin:-> releasedir / (0,)
DEBUG:fuse.log-mixin:<- releasedir 0
DEBUG:fuse.log-mixin:-> getattr /two (None,)
DEBUG:fuse.log-mixin:<- getattr {'st_atime': 1601978551.8125505, 'st_ctime': 1601978551.752551, 'st_gid': 1000, 'st_mode': 33204, 'st_mtime': 1601978551.752551, 'st_nlink': 1, 'st_size': 41, 'st_uid': 1000}
DEBUG:fuse.log-mixin:-> getattr /one (None,)
DEBUG:fuse.log-mixin:<- getattr {'st_atime': 1602027513.9553053, 'st_ctime': 1602027513.8993046, 'st_gid': 1000, 'st_mode': 33204, 'st_mtime': 1602027513.8993046, 'st_nlink': 1, 'st_size': 3, 'st_uid': 1000}

DEBUG:fuse.log-mixin:-> getxattr /hi ('security.capability',)
DEBUG:fuse.log-mixin:<- getxattr '[Errno 95] Operation not supported'
DEBUG:fuse:FUSE operation getxattr raised a <class 'fuse.FuseOSError'>, returning errno 95.
Traceback (most recent call last):
  File "/home/etinaude/Documents/git/340/A2/fuse.py", line 731, in _wrapper
    return func(*args, **kwargs) or 0
  File "/home/etinaude/Documents/git/340/A2/fuse.py", line 906, in getxattr
    ret = self.operations('getxattr', path.decode(self.encoding),
  File "/home/etinaude/Documents/git/340/A2/fuse.py", line 1240, in __call__
    ret = getattr(self, op)(path, *args)
  File "/home/etinaude/Documents/git/340/A2/fuse.py", line 1124, in getxattr
    raise FuseOSError(ENOTSUP)
fuse.FuseOSError: [Errno 95] Operation not supported
DEBUG:fuse.log-mixin:-> write /hi (b'hello', 0, 1)
**************** defaultdict(<class 'bytes'>, {}) *** /hi ***********************
DEBUG:fuse.log-mixin:<- write 5
DEBUG:fuse.log-mixin:-> flush /hi (1,)
DEBUG:fuse.log-mixin:<- flush 0
DEBUG:fuse.log-mixin:-> release /hi (1,)
DEBUG:fuse.log-mixin:<- release None


DEBUG:fuse.log-mixin:-> open /hi (32768,)
DEBUG:fuse.log-mixin:<- open None
ERROR:fuse:Uncaught exception from FUSE operation open, returning errno.EINVAL.
Traceback (most recent call last):
  File "/home/etinaude/Documents/git/340/A2/fuse.py", line 731, in _wrapper
    return func(*args, **kwargs) or 0
  File "/home/etinaude/Documents/git/340/A2/fuse.py", line 831, in open
    fi.fh = self.operations('open', path.decode(self.encoding),
TypeError: an integer is required (got type NoneType)
DEBUG:fuse.log-mixin:-> getattr / (None,)
DEBUG:fuse.log-mixin:<- getattr {'st_atime': 1601978543.744611, 'st_ctime': 1601978543.7086115, 'st_gid': 1000, 'st_mode': 16893, 'st_mtime': 1601978543.7086115, 'st_nlink': 2, 'st_size': 4096, 'st_uid': 1000}
DEBUG:fuse.log-mixin:-> opendir / ()
DEBUG:fuse.log-mixin:<- opendir 0
DEBUG:fuse.log-mixin:-> readdir / (0,)
DEBUG:fuse.log-mixin:<- readdir <generator object Fuse2.readdir at 0x7f46719b0510>
DEBUG:fuse.log-mixin:-> releasedir / (0,)
DEBUG:fuse.log-mixin:<- releasedir 0
DEBUG:fuse.log-mixin:-> getattr /one (None,)
DEBUG:fuse.log-mixin:<- getattr {'st_atime': 1602027513.9553053, 'st_ctime': 1602027513.8993046, 'st_gid': 1000, 'st_mode': 33204, 'st_mtime': 1602027513.8993046, 'st_nlink': 1, 'st_size': 3, 'st_uid': 1000}
DEBUG:fuse.log-mixin:-> getattr /two (None,)
DEBUG:fuse.log-mixin:<- getattr {'st_atime': 1601978551.8125505, 'st_ctime': 1601978551.752551, 'st_gid': 1000, 'st_mode': 33204, 'st_mtime': 1601978551.752551, 'st_nlink': 1, 'st_size': 41, 'st_uid': 1000}
DEBUG:fuse.log-mixin:-> getattr / (None,)
DEBUG:fuse.log-mixin:<- getattr {'st_atime': 1601978543.744611, 'st_ctime': 1601978543.7086115, 'st_gid': 1000, 'st_mode': 16893, 'st_mtime': 1601978543.7086115, 'st_nlink': 2, 'st_size': 4096, 'st_uid': 1000}
DEBUG:fuse.log-mixin:-> opendir / ()
DEBUG:fuse.log-mixin:<- opendir 0
DEBUG:fuse.log-mixin:-> readdir / (0,)
DEBUG:fuse.log-mixin:<- readdir <generator object Fuse2.readdir at 0x7f46719b0510>
DEBUG:fuse.log-mixin:-> releasedir / (0,)
DEBUG:fuse.log-mixin:<- releasedir 0
